[2024-04-28T16:43:18.554+0000] {task_context_logger.py:104} ERROR - Executor reports task instance <TaskInstance: test_scheduled_dag_20minutes.extract scheduled__2024-04-28T16:20:00+00:00 [queued]> finished (failed) although the task says it's queued. (Info: None) Was the task killed externally?
